<?xml version="1.0" ?>
<!-- =================================================================================== -->
<!-- |    This document was autogenerated by xacro from smartcar.urdf.xacro            | -->
<!-- |    EDITING THIS FILE BY HAND IS NOT RECOMMENDED                                 | -->
<!-- =================================================================================== -->
<robot name="smartcar">
  <material name="body_material">
    <color rgba="1 0 0 1"/>
  </material>
  <material name="wheel_material">
    <color rgba="0 0 0 1"/>
  </material>
  <material name="imu_material">
    <color rgba="1 1 0 1"/>
  </material>
  <material name="lidar_material">
    <color rgba="0 0 0 1"/>
  </material>
  <material name="footprint_material">
    <color rgba="0 1 1 0.1"/>
  </material>
  <link name="base_link">
    <origin rpy="0 0 0" xyz="0 0 0"/>
  </link>
  <joint name="base_to_chassis" type="fixed">
    <origin rpy="0 0 0" xyz="0 0 0.032"/>
    <parent link="base_link"/>
    <child link="chassis_link"/>
  </joint>
  <link name="chassis_link">
    <visual>
      <geometry>
        <box size="0.257 0.17 0.0125"/>
      </geometry>
      <origin rpy="0 0 0" xyz="0 0 0"/>
      <material name="body_material"/>
    </visual>
    <collision>
      <geometry>
        <box size="0.257 0.17 0.0125"/>
      </geometry>
      <origin rpy="0 0 0" xyz="0 0 0"/>
    </collision>
    <inertial>
      <mass value="5.0"/>
      <origin rpy="0 0 0" xyz="0 0 0"/>
      <!-- <inertia ixx="0.02" ixy="0.0" ixz="0.0" iyy="0.02" iyz="0.0" izz="0.02"/> -->
      <inertia ixx="0.0121" ixy="0.0" ixz="0.0" iyy="0.0276" iyz="0.0" izz="0.0396"/>
    </inertial>
  </link>
  <gazebo reference="chassis_link">
    <material>Gazebo/Red</material>
  </gazebo>
  <joint name="base_to_footprint" type="fixed">
    <parent link="base_link"/>
    <child link="base_footprint"/>
  </joint>
  <link name="base_footprint">
    <visual>
      <origin rpy="0 0 0" xyz="0 0 0.0001"/>
      <geometry>
        <box size="0.257 0.17 0"/>
      </geometry>
      <material name="footprint_material"/>
    </visual>
  </link>
  <gazebo reference="base_footprint">
    <material>Gazebo/TurquoiseGlow</material>
  </gazebo>
  <joint name="front_left_wheel_steer_joint" type="revolute">
    <origin rpy="0 0 0" xyz="0.1285 0.085 0.032"/>
    <parent link="base_link"/>
    <child link="front_left_wheel_steer_link"/>
    <axis xyz="0 0 1"/>
    <limit effort="10" lower="-0.7853981633974483" upper="0.7853981633974483" velocity="1"/>
  </joint>
  <link name="front_left_wheel_steer_link">
    <origin rpy="0 0 0" xyz="0 0 0"/>
    <visual>
      <geometry>
        <box size="0.01 0.01 0.01"/>
      </geometry>
      <origin rpy="0 0 0" xyz="0 0 0"/>
    </visual>
    <collision>
      <geometry>
        <box size="0.01 0.01 0.01"/>
      </geometry>
      <origin rpy="0 0 0" xyz="0 0 0"/>
    </collision>
    <inertial>
      <mass value="0.1"/>
      <origin rpy="0 0 0" xyz="0 0 0"/>
      <inertia ixx="0.00005" ixy="0.0" ixz="0.0" iyy="0.00005" iyz="0.0" izz="0.00005"/>
    </inertial>
  </link>
  <gazebo reference="front_left_wheel_steer_link">
    <material>Gazebo/Red</material>
  </gazebo>
  <joint name="front_left_wheel_joint" type="continuous">
    <origin rpy="0 0 0" xyz="0 0 0"/>
    <parent link="front_left_wheel_steer_link"/>
    <child link="front_left_wheel_link"/>
    <axis xyz="0 1 0"/>
  </joint>
  <link name="front_left_wheel_link">
    <visual>
      <geometry>
        <cylinder length="0.025" radius="0.032"/>
      </geometry>
      <origin rpy="1.5707963267948966 0 0" xyz="0 0.0125 0"/>
      <material name="wheel_material"/>
    </visual>
    <collision>
      <geometry>
        <cylinder length="0.025" radius="0.032"/>
      </geometry>
      <origin rpy="1.5707963267948966 0 0" xyz="0 0.0125 0"/>
    </collision>
    <inertial>
      <mass value="0.2"/>
      <origin rpy="0 0 0" xyz="0 0 0"/>
      <inertia ixx="0.0001" ixy="0.0" ixz="0.0" iyy="0.0001" iyz="0.0" izz="0.0001"/>
    </inertial>
  </link>
  <gazebo reference="front_left_wheel_link">
    <material>Gazebo/Black</material>
  </gazebo>
  <joint name="front_right_wheel_steer_joint" type="revolute">
    <origin rpy="0 0 0" xyz="0.1285 -0.085 0.032"/>
    <parent link="base_link"/>
    <child link="front_right_wheel_steer_link"/>
    <axis xyz="0 0 1"/>
    <limit effort="10" lower="-0.7853981633974483" upper="0.7853981633974483" velocity="1"/>
  </joint>
  <link name="front_right_wheel_steer_link">
    <origin rpy="0 0 0" xyz="0 0 0"/>
    <visual>
      <geometry>
        <box size="0.01 0.01 0.01"/>
      </geometry>
      <origin rpy="0 0 0" xyz="0 0 0"/>
    </visual>
    <collision>
      <geometry>
        <box size="0.01 0.01 0.01"/>
      </geometry>
      <origin rpy="0 0 0" xyz="0 0 0"/>
    </collision>
    <inertial>
      <mass value="0.1"/>
      <origin rpy="0 0 0" xyz="0 0 0"/>
      <inertia ixx="0.00005" ixy="0.0" ixz="0.0" iyy="0.00005" iyz="0.0" izz="0.00005"/>
    </inertial>
  </link>
  <gazebo reference="front_right_wheel_steer_link">
    <material>Gazebo/Red</material>
  </gazebo>
  <joint name="front_right_wheel_joint" type="continuous">
    <origin rpy="0 0 0" xyz="0 0 0"/>
    <parent link="front_right_wheel_steer_link"/>
    <child link="front_right_wheel_link"/>
    <axis xyz="0 1 0"/>
  </joint>
  <link name="front_right_wheel_link">
    <visual>
      <geometry>
        <cylinder length="0.025" radius="0.032"/>
      </geometry>
      <origin rpy="1.5707963267948966 0 0" xyz="0 -0.0125 0"/>
      <material name="wheel_material"/>
    </visual>
    <collision>
      <geometry>
        <cylinder length="0.025" radius="0.032"/>
      </geometry>
      <origin rpy="1.5707963267948966 0 0" xyz="0 -0.0125 0"/>
    </collision>
    <inertial>
      <mass value="0.2"/>
      <origin rpy="0 0 0" xyz="0 0 0"/>
      <inertia ixx="0.0001" ixy="0.0" ixz="0.0" iyy="0.0001" iyz="0.0" izz="0.0001"/>
    </inertial>
  </link>
  <gazebo reference="front_right_wheel_link">
    <material>Gazebo/Black</material>
  </gazebo>
  <joint name="back_left_wheel_joint" type="continuous">
    <origin rpy="0 0 0" xyz="-0.1285 0.085 0.032"/>
    <parent link="base_link"/>
    <child link="back_left_wheel_link"/>
    <axis xyz="0 1 0"/>
  </joint>
  <link name="back_left_wheel_link">
    <visual>
      <geometry>
        <cylinder length="0.025" radius="0.032"/>
      </geometry>
      <origin rpy="1.5707963267948966 0 0" xyz="0 0.0125 0"/>
      <material name="wheel_material"/>
    </visual>
    <collision>
      <geometry>
        <cylinder length="0.025" radius="0.032"/>
      </geometry>
      <origin rpy="1.5707963267948966 0 0" xyz="0 0.0125 0"/>
    </collision>
    <inertial>
      <mass value="0.2"/>
      <origin rpy="0 0 0" xyz="0 0 0"/>
      <inertia ixx="0.0001" ixy="0.0" ixz="0.0" iyy="0.0001" iyz="0.0" izz="0.0001"/>
    </inertial>
  </link>
  <gazebo reference="back_left_wheel_link">
    <material>Gazebo/Black</material>
  </gazebo>
  <joint name="back_right_wheel_joint" type="continuous">
    <origin rpy="0 0 0" xyz="-0.1285 -0.085 0.032"/>
    <parent link="base_link"/>
    <child link="back_right_wheel_link"/>
    <axis xyz="0 1 0"/>
  </joint>
  <link name="back_right_wheel_link">
    <visual>
      <geometry>
        <cylinder length="0.025" radius="0.032"/>
      </geometry>
      <origin rpy="1.5707963267948966 0 0" xyz="0 -0.0125 0"/>
      <material name="wheel_material"/>
    </visual>
    <collision>
      <geometry>
        <cylinder length="0.025" radius="0.032"/>
      </geometry>
      <origin rpy="1.5707963267948966 0 0" xyz="0 -0.0125 0"/>
    </collision>
    <inertial>
      <mass value="0.2"/>
      <origin rpy="0 0 0" xyz="0 0 0"/>
      <inertia ixx="0.0001" ixy="0.0" ixz="0.0" iyy="0.0001" iyz="0.0" izz="0.0001"/>
    </inertial>
  </link>
  <gazebo reference="back_right_wheel_link">
    <material>Gazebo/Black</material>
  </gazebo>
  <link name="imu_link">
    <visual>
      <origin rpy="0 0 0" xyz="0 0 0"/>
      <geometry>
        <box size="0.01 0.01 0.01"/>
      </geometry>
      <material name="imu_material"/>
    </visual>
    <collision>
      <origin rpy="0 0 0" xyz="0 0 0"/>
      <geometry>
        <box size="0.01 0.01 0.01"/>
      </geometry>
    </collision>
    <inertial>
      <mass value="0.1"/>
      <origin rpy="0 0 0" xyz="0 0 0"/>
      <inertia ixx="0.00001" ixy="0.0" ixz="0.0" iyy="0.00001" iyz="0.0" izz="0.00001"/>
    </inertial>
  </link>
  <gazebo reference="imu_link">
    <sensor name="my_imu" type="imu">
      <always_on>true</always_on>
      <update_rate>30</update_rate>
      <plugin filename="libgazebo_ros_imu_sensor.so" name="my_imu_plugin">
        <ros>
          <remapping>~/out:=imu_data</remapping>
        </ros>
      </plugin>
    </sensor>
    <material>Gazebo/Yellow</material>
  </gazebo>
  <joint name="base_to_imu" type="fixed">
    <origin rpy="0 0 0" xyz="0 0 0.064"/>
    <parent link="base_link"/>
    <child link="imu_link"/>
  </joint>
  <link name="sllidar_base_link">
    <visual>
      <origin rpy="0 0 0" xyz="0 0 0"/>
      <geometry>
        <cylinder length="0.025" radius="0.025"/>
      </geometry>
      <material name="lidar_material"/>
    </visual>
    <collision>
      <origin rpy="0 0 0" xyz="0 0 0"/>
      <geometry>
        <cylinder length="0.025" radius="0.025"/>
      </geometry>
    </collision>
    <inertial>
      <mass value="0.2"/>
      <origin rpy="0 0 0" xyz="0 0 0"/>
      <inertia ixx="0.0001" ixy="0.0" ixz="0.0" iyy="0.0001" iyz="0.0" izz="0.0001"/>
    </inertial>
  </link>
  <gazebo reference="sllidar_base_link">
    <sensor name="sensor_gpu_ray" type="ray">
      <visualize>true</visualize>
      <ray>
        <scan>
          <horizontal>
            <samples>360</samples>
            <resolution>1.0</resolution>
            <min_angle>-3.141592653589793</min_angle>
            <max_angle>3.141592653589793</max_angle>
          </horizontal>
        </scan>
        <range>
          <min>0.5</min>
          <max>50.0</max>
        </range>
      </ray>
      <always_on>true</always_on>
      <plugin filename="libgazebo_ros_ray_sensor.so" name="laser_scan_plugin">
        <output_type>sensor_msgs/LaserScan</output_type>
        <frameName>sllidar_base_link</frameName>
        <topicName>/scan</topicName>
        <remapping>~/out:=scan</remapping>
        <robotNamespace>/</robotNamespace>
        <updateRate>30.0</updateRate>
      </plugin>
    </sensor>
    <material>Gazebo/Purple</material>
  </gazebo>
  <joint name="base_to_lidar" type="fixed">
    <origin rpy="0 0 0" xyz="0.1285 0 0.096"/>
    <parent link="base_link"/>
    <child link="sllidar_base_link"/>
  </joint>
  <gazebo>
    <plugin filename="libcar_gazebo_plugin.so" name="car_gazebo_plugin"/>
  </gazebo>
</robot>
